<?xml version="1.0"?>
<robot name="template">

    <!--World & Base -->	
    <link name="world">
    </link> 
    <joint name="base_joint" type="fixed">
        <origin xyz="0 0 0" rpy="0 0 0"/> 
        <parent link="world"/>
        <child link="base"/>
        <axis xyz="0 0 0"/>
    </joint>
    <link name="base">
        <inertial>
            <origin xyz="0 0 0" rpy="0 0 0"/>
            <mass value="1.0"/>
            <inertia ixx="0.1" iyy="0.1" izz="0.1" ixy="0" ixz="0" iyz="0"/>
        </inertial>
        <visual>
            <origin xyz="0 0 0" rpy="0 0 0"/>
            <geometry>
                <cylinder length="0.05" radius="0.02"/>
            </geometry> 
        </visual>
    </link> 

    <!--First Joint & Link  --> 
    <joint name="joint1" type="revolute">
        <origin xyz="0 0 0.0501" rpy="0 0 0"/> 
        <parent link="base"/>
        <child link="link1"/>
        <limit effort="300" velocity="100" lower="-3.14" upper="3.14" />
        <axis xyz="0 0 1"/>
    </joint> 
    <link name="link1">
        <inertial>
            <origin xyz="0 0.04 0" rpy="0 0 0"/>
            <mass value="1"/>
            <inertia ixx="0.001" iyy="0.001" izz="0.002" ixy="0" ixz="0" iyz="0"/>
        </inertial>
		<visual>
            <origin xyz="0 0.035 0" rpy="0 0 0"/>
            <geometry>
				<box size="0.02 0.08 0.02"/>
            </geometry>	
        </visual>
    </link>

    <!--Second Joint & Link  --> 
    <joint name="joint2" type="revolute">
        <origin xyz="0 0.085 0" rpy="0 0 0"/> 
        <parent link="link1"/>
        <child link="link2"/>
        <limit effort="300" velocity="100" lower="-3.14" upper="3.14" />
        <axis xyz="0 0 1"/>
    </joint> 
    <link name="link2">
        <inertial>
            <origin xyz="0 0.04 0" rpy="0 0 0"/>
            <mass value="1"/>
            <inertia ixx="0.001" iyy="0.001" izz="0.002" ixy="0" ixz="0" iyz="0"/>
        </inertial>
        <visual>
            <origin xyz="0 0.035 0" rpy="0 0 0"/>
            <geometry>
                <box size="0.02 0.08 0.02"/>
            </geometry> 
        </visual>
    </link>

    <!--Third Joint & Link  --> 
    <joint name="joint3" type="revolute">
        <origin xyz="0 0.085 0" rpy="0 0 0"/> 
        <parent link="link2"/>
        <child link="link3"/>
        <limit effort="300" velocity="100" lower="-3.14" upper="3.14" />
        <axis xyz="0 0 1"/>
    </joint> 
    <link name="link3">
        <inertial>
            <origin xyz="0 0.04 0" rpy="0 0 0"/>
            <mass value="1"/>
            <inertia ixx="0.001" iyy="0.001" izz="0.002" ixy="0" ixz="0" iyz="0"/>
        </inertial>
        <visual>
            <origin xyz="0 0.035 0" rpy="0 0 0"/>
            <geometry>
                <box size="0.02 0.08 0.02"/>
            </geometry> 
        </visual>
    </link>

    <!-- Legend for the libsea_plugin.so custom plugin 
    
        # The stiffness of the SEA joint is defined in the <stiffness> tag
        #
        # The two other tags enable the generation and publication of additional topics: the state publisher and 
        #      enable the subscription to external torque topic
    -->
    <gazebo>
        <plugin name="sea_j1" filename="libsea_plugin.so">
            <joint>joint1</joint>  
            <namespace>template_robot</namespace>
            <stiffness>10</stiffness>
            <pub_eltau>true</pub_eltau>
            <pub_state>true</pub_state>
            <sub_ext_tau>true</sub_ext_tau>
        </plugin>
    </gazebo>
    <gazebo>
        <plugin name="sea_j2" filename="libsea_plugin.so">
            <joint>joint2</joint>  
            <namespace>template_robot</namespace>
            <stiffness>10</stiffness>
            <pub_eltau>true</pub_eltau>
            <pub_state>true</pub_state>
            <sub_ext_tau>true</sub_ext_tau>
        </plugin>
    </gazebo>
    <gazebo>
        <plugin name="sea_j3" filename="libsea_plugin.so">
            <joint>joint3</joint>  
            <namespace>template_robot</namespace>
            <stiffness>10</stiffness>
            <pub_eltau>true</pub_eltau>
            <pub_state>true</pub_state>
            <sub_ext_tau>true</sub_ext_tau>
        </plugin>
    </gazebo>

</robot>
