<?xml version="1.0"?>
<robot name="template">

    <!--World & Base -->	
    <link name="world">
    </link> 
    <joint name="base_joint" type="fixed">
        <origin xyz="0 0 0" rpy="0 0 0"/> 
        <parent link="world"/>
        <child link="base"/>
        <axis xyz="0 0 0"/>
    </joint>
    <link name="base">
        <inertial>
            <origin xyz="0 0 0" rpy="0 0 0"/>
            <mass value="1.0"/>
            <inertia ixx="0.1" iyy="0.1" izz="0.1" ixy="0" ixz="0" iyz="0"/>
        </inertial>
        <visual>
            <origin xyz="0 0 0" rpy="0 0 0"/>
            <geometry>
                <cylinder length="0.05" radius="0.02"/>
            </geometry> 
        </visual>
    </link> 

    <!--First Joint & Link  --> 
    <joint name="joint1" type="revolute">
        <origin xyz="0 0 0.0501" rpy="0 0 0"/> 
        <parent link="base"/>
        <child link="link1"/>
        <limit effort="300" velocity="100" lower="-3.14" upper="3.14" />
        <axis xyz="0 0 1"/>
    </joint> 
    <link name="link1">
        <inertial>
            <origin xyz="0 0.04 0" rpy="0 0 0"/>
            <mass value="1"/>
            <inertia ixx="0.001" iyy="0.001" izz="0.002" ixy="0" ixz="0" iyz="0"/>
        </inertial>
		<visual>
            <origin xyz="0 0.035 0" rpy="0 0 0"/>
            <geometry>
				<box size="0.02 0.08 0.02"/>
            </geometry>	
        </visual>
    </link>

    <!-- Legend for the libadvanced_plugin.so custom plugin 
    
        # The type of actuator is fixed i.e., qbMove
        # The control_type can be chosen as: [0,1,2]
        #      - [0] -> references are directly the motor positions
        #      - [1] -> references are used as equilibirium position and preset
        #      - [2] -> first reference is used as direct joint torque, while the second is not used (marked as disabled)
        #
        # The three other tags enable the generation and publication of additional topics: the elastic topic publisher, the state publisher and 
        #      enable the subscription to external torque topic

    -->
    <gazebo>
        <plugin name="advanced_vsa_j1" filename="libadvanced_plugin.so">
            <joint>joint1</joint>
            <control_type>1</control_type>
            <pub_eltau>true</pub_eltau>
            <pub_state>true</pub_state>
            <sub_ext_tau>true</sub_ext_tau>
        </plugin>
    </gazebo>

    <!-- Legend for the libsea_plugin.so custom plugin 
    
        # The stiffness of the SEA joint is defined in the <stiffness> tag
        #
        # The two other tags enable the generation and publication of additional topics: the state publisher and 
        #      enable the subscription to external torque topic
    -->
<!--     <gazebo>
        <plugin name="sea_j1" filename="libsea_plugin.so">
            <joint>joint1</joint>  
            <namespace>template_robot</namespace>
            <stiffness>100</stiffness>
            <pub_eltau>true</pub_eltau>
            <pub_state>true</pub_state>
            <sub_ext_tau>true</sub_ext_tau>
        </plugin>
    </gazebo> -->



</robot>
